Workbook
Name Slicer_Completion_Status: #N/A
Name Slicer_Course_Category1: #N/A
Name Slicer_Course_Level: #N/A
Name Slicer_Duration_months: #N/A
Name Slicer_Instructor_Name: #N/A
Name Slicer_Mode: #N/A
Name Slicer_Months: #N/A
Name Slicer_Nationality: #N/A
Name Slicer_Payment_Status: #N/A
Name Slicer_Terms_Completed: #N/A

Sheet Enrollment_Data
A1: Student_ID | B1: Enrollment_Date | C1: Course | D1: Course_Category | E1: Course_Level | F1: Duration_months | G1: Daily_Learning_Time(hr) | H1: Course_Fee_AED | I1: Terms_Completed | J1: Amount_Paid_AED | K1: Payment_Status | L1: Mode | M1: Branch | N1: Instructor_Name | O1: Nationality | P1: Completion_Status | Q1: pending Revenue | R1: Revenue
A2: S10000 | B2: 45334 | C2: Financial Accounting | D2: Finance | E2: Advanced | F2: 6 | G2: 1 | H2: 7038 | I2: 1 | J2: 2346 | K2: Ongoing | L2: Hybrid | M2: Al Ain | N2: Ali Hassan | O2: Sri Lanka | P2: Ongoing | Q2: =Table1[[#This Row],[Course_Fee_AED]]-Table1[[#This Row],[Amount_Paid_AED]] -> 4692 | R2: =Table1[[#This Row],[Course_Fee_AED]]-Table1[[#This Row],[pending Revenue]] -> 2346
A3: S10001 | B3: 45600 | C3: Corporate Administration (ATCA) | D3: Administration | E3: Basic | F3: 3 | G3: 1 | H3: 4521 | I3: 3 | J3: 4521 | K3: Cleared | L3: Hybrid | M3: Ras Al Khaimah | N3: Lina George | O3: Philippines | P3: Ongoing | Q3: =Table1[[#This Row],[Course_Fee_AED]]-Table1[[#This Row],[Amount_Paid_AED]] -> 0 | R3: =Table1[[#This Row],[Course_Fee_AED]]-Table1[[#This Row],[pending Revenue]] -> 4521
A4: S10002 | B4: 45649 | C4: Quantity Surveying (QS) | D4: Construction | E4: Basic | F4: 3 | G4: 1 | H4: 7086 | I4: 3 | J4: 7086 | K4: Cleared | L4: Hybrid | M4: Al Ain | N4: Noura Al Mansoori | O4: Jordan | P4: Completed | Q4: =Table1[[#This Row],[Course_Fee_AED]]-Table1[[#This Row],[Amount_Paid_AED]] -> 0 | R4: =Table1[[#This Row],[Course_Fee_AED]]-Table1[[#This Row],[pending Revenue]] -> 7086
A5: S10003 | B5: 45578 | C5: Digital Marketing | D5: Marketing | E5: Advanced | F5: 6 | G5: 1 | H5: 4791 | I5: 3 | J5: 4791 | K5: Cleared | L5: Offline | M5: Abu Dhabi | N5: Sara Ahmed | O5: Pakistan | P5: Ongoing | Q5: =Table1[[#This Row],[Course_Fee_AED]]-Table1[[#This Row],[Amount_Paid_AED]] -> 0 | R5: =Table1[[#This Row],[Course_Fee_AED]]-Table1[[#This Row],[pending Revenue]] -> 4791
A6: S10004 | B6: 45352 | C6: Logistics & Supply Chain | D6: Logistics | E6: Advanced | F6: 6 | G6: 1 | H6: 4375 | I6: 3 | J6: 4374 | K6: Ongoing | L6: Hybrid | M6: Dubai | N6: Omar Farooq | O6: India | P6: Completed | Q6: =Table1[[#This Row],[Course_Fee_AED]]-Table1[[#This Row],[Amount_Paid_AED]] -> 1 | R6: =Table1[[#This Row],[Course_Fee_AED]]-Table1[[#This Row],[pending Revenue]] -> 4374
A7: S10005 | B7: 45581 | C7: Python for Data Analysis | D7: Programming | E7: Basic | F7: 3 | G7: 1 | H7: 4903 | I7: 3 | J7: 4902 | K7: Ongoing | L7: Offline | M7: Ras Al Khaimah | N7: Maria Joseph | O7: Pakistan | P7: Completed | Q7: =Table1[[#This Row],[Course_Fee_AED]]-Table1[[#This Row],[Amount_Paid_AED]] -> 1 | R7: =Table1[[#This Row],[Course_Fee_AED]]-Table1[[#This Row],[pending Revenue]] -> 4902
A8: S10006 | B8: 45509 | C8: SAP FICO | D8: ERP | E8: Basic | F8: 3 | G8: 1 | H8: 7758 | I8: 1 | J8: 2586 | K8: Ongoing | L8: Online | M8: Ras Al Khaimah | N8: Lina George | O8: Egypt | P8: Completed | Q8: =Table1[[#This Row],[Course_Fee_AED]]-Table1[[#This Row],[Amount_Paid_AED]] -> 5172 | R8: =Table1[[#This Row],[Course_Fee_AED]]-Table1[[#This Row],[pending Revenue]] -> 2586
A9: S10007 | B9: 45328 | C9: Logistics & Supply Chain | D9: Logistics | E9: Advanced | F9: 6 | G9: 1 | H9: 5096 | I9: 3 | J9: 5094 | K9: Ongoing | L9: Online | M9: Ajman | N9: Hassan Ali | O9: India | P9: Completed | Q9: =Table1[[#This Row],[Course_Fee_AED]]-Table1[[#This Row],[Amount_Paid_AED]] -> 2 | R9: =Table1[[#This Row],[Course_Fee_AED]]-Table1[[#This Row],[pending Revenue]] -> 5094
A10: S10008 | B10: 45625 | C10: Corporate Administration (ATCA) | D10: Administration | E10: Basic | F10: 3 | G10: 1 | H10: 6797 | I10: 2 | J10: 4530 | K10: Ongoing | L10: Online | M10: Sharjah | N10: Lina George | O10: Nigeria | P10: Completed | Q10: =Table1[[#This Row],[Course_Fee_AED]]-Table1[[#This Row],[Amount_Paid_AED]] -> 2267 | R10: =Table1[[#This Row],[Course_Fee_AED]]-Table1[[#This Row],[pending Revenue]] -> 4530
A11: S10009 | B11: 45491 | C11: SAP MM | D11: ERP | E11: Advanced | F11: 6 | G11: 1 | H11: 7620 | I11: 2 | J11: 5080 | K11: Ongoing | L11: Hybrid | M11: Dubai | N11: Omar Farooq | O11: Pakistan | P11: Ongoing | Q11: =Table1[[#This Row],[Course_Fee_AED]]-Table1[[#This Row],[Amount_Paid_AED]] -> 2540 | R11: =Table1[[#This Row],[Course_Fee_AED]]-Table1[[#This Row],[pending Revenue]] -> 5080
A12: S10010 | B12: 45347 | C12: Python for Data Analysis | D12: Programming | E12: Basic | F12: 3 | G12: 1 | H12: 4177 | I12: 2 | J12: 2784 | K12: Ongoing | L12: Offline | M12: Dubai | N12: Lina George | O12: Nepal | P12: Completed | Q12: =Table1[[#This Row],[Course_Fee_AED]]-Table1[[#This Row],[Amount_Paid_AED]] -> 1393 | R12: =Table1[[#This Row],[Course_Fee_AED]]-Table1[[#This Row],[pending Revenue]] -> 2784
A13: S10011 | B13: 45310 | C13: Digital Marketing | D13: Marketing | E13: Advanced | F13: 6 | G13: 1 | H13: 4589 | I13: 3 | J13: 4587 | K13: Ongoing | L13: Hybrid | M13: Dubai | N13: Aisha Rahman | O13: UAE | P13: Ongoing | Q13: =Table1[[#This Row],[Course_Fee_AED]]-Table1[[#This Row],[Amount_Paid_AED]] -> 2 | R13: =Table1[[#This Row],[Course_Fee_AED]]-Table1[[#This Row],[pending Revenue]] -> 4587
... A2001: S11999 | B2001: 45380 | C2001: Quantity Surveying (QS) | D2001: Construction | E2001: Advanced | F2001: 6 | G2001: 1 | H2001: 6805 | I2001: 3 | J2001: 6804 | K2001: Ongoing | L2001: Online | M2001: Al Ain | N2001: Khalid Omar | O2001: Nigeria | P2001: Ongoing | Q2001: =Table1[[#This Row],[Course_Fee_AED]]-Table1[[#This Row],[Amount_Paid_AED]] -> 1 | R2001: =Table1[[#This Row],[Course_Fee_AED]]-Table1[[#This Row],[pending Revenue]] -> 6804

Sheet Pivot &Calculations
A2: 1 | B2: TOTAL STUDENTS | F2: =COUNTA(Table1[Student_ID]) -> 2000 | H2: 1 | I2: Monthly enrollment trend | L2: 6 | M2: REVENUE GENERATED BY COURSE AND PENDING REVENUE | P2: 9 | Q2: Payment Status Summery
A3: 2 | B3: TOTAL COURSE FEE/total potential revenue | F3: =SUM(Enrollment_Data!H:H) -> 13923453 | I3: Row Labels | J3: Count of Student_ID | M3: Row Labels | N3: Sum of Revenue | O3: Sum of pending Revenue | Q3: Row Labels | R3: Count of Student_ID
A4: 3 | B4: TOTAL REVENUE COLLECTED | F4: =SUM(Enrollment_Data!R:R) -> 9142743 | I4: Jan | J4: 167 | M4: AI Generalist | N4: 1028315 | O4: 474269 | Q4: Cleared | R4: 214
A5: 4 | B5: pending revenue | F5: =SUM(Enrollment_Data!H:H)-SUM(Enrollment_Data!R:R) -> 4780710 | I5: Feb | J5: 158 | M5: Corporate Administration (ATCA) | N5: 616867 | O5: 296972 | Q5: Ongoing | R5: 1786
A6: 5 | B6: AVERAGE COURSE FEE | F6: =AVERAGE(Enrollment_Data!H:H) -> 6961.7265 | I6: Mar | J6: 146 | M6: Cyber Security | N6: 1177143 | O6: 665896 | Q6: Grand Total | R6: 2000
B7: PERCENTAGE OF TOTAL REVENUE COLLECTED | F7: =F4/F3*100 -> 65.664336 | I7: Apr | J7: 162 | M7: Data Analytics | N7: 630554 | O7: 365153
B8: PERCENTAGE OF TOTAL PENDING REVENUE | F8: =F5/F3*100 -> 34.335664 | I8: May | J8: 157 | M8: Digital Marketing | N8: 594293 | O8: 307166 | P8: 10 | Q8: COMPLETION STATUS VS PENDING REVENUE
A9: 6 | B9: Highest student enrollment course category | E9: =I53 -> ERP | I9: Jun | J9: 154 | M9: Financial Accounting | N9: 555789 | O9: 275432 | Q9: Row Labels | R9: Sum of Revenue | S9: Sum of pending Revenue
A10: 7 | B10: Highest revenue generated branch | E10: =M38 -> Abu Dhabi | I10: Jul | J10: 160 | M10: Logistics & Supply Chain | N10: 492344 | O10: 272335 | Q10: Completed | R10: 4557988 | S10: 2276202
A11: 8 | B11: Lowest revenue generated branch | E11: =M39 -> Sharjah | I11: Aug | J11: 187 | M11: Power BI & Business Intelligence | N11: 360011 | O11: 202335 | Q11: Ongoing | R11: 4584755 | S11: 2504508
A12: 9 | B12: Highest revenue generated course | E12: =M6 -> Cyber Security | I12: Sep | J12: 185 | M12: Project Management | N12: 567794 | O12: 269384 | Q12: Grand Total | R12: 9142743 | S12: 4780710
A13: 10 | B13: Instructor with highest students | E13: =D35 -> Ali Hassan | I13: Oct | J13: 164 | M13: Python for Data Analysis | N13: 513322 | O13: 226920
I14: Nov | J14: 174 | M14: Quantity Surveying (QS) | N14: 651504 | O14: 316648
I15: Dec | J15: 186 | M15: SAP FICO | N15: 778273 | O15: 453766
I16: Grand Total | J16: 2000 | M16: SAP MM | N16: 782798 | O16: 460279 | Q16: Course completion status vs pending Revenue
A17: 11 | B17: NUMBER OF COMPLETED STUDENTS | F17: =COUNTIF(Enrollment_Data!P:P,"completed") -> 993 | J17: =GETPIVOTDATA("Student_ID",$I$3) -> 2000 | M17: UAE VAT & Taxation | N17: 393736 | O17: 194155 | Q17: Sum of pending Revenue | R17: Column Labels
A18: 12 | B18: NUMBER OF ONGOING STUDENTS | F18: =COUNTIF(Enrollment_Data!P:P,"Ongoing") -> 1007 | M18: Grand Total | N18: 9142743 | O18: 4780710 | Q18: Row Labels | R18: Completed | S18: Ongoing | T18: Grand Total
A19: 13 | B19: Most enrolled course | E19: =D56 -> Data Analytics | H19: 3 | I19: Student enrollment vs Mode of class | Q19: AI Generalist | R19: 222809 | S19: 251460 | T19: 474269
A20: 14 | B20: Least enrolled course | E20: =D61 -> Project Management | L20: 7 | M20: Monthly Revenue Trend | Q20: Corporate Administration (ATCA) | R20: 163304 | S20: 133668 | T20: 296972
I21: Row Labels | J21: Count of Student_ID | M21: Row Labels | N21: Sum of Revenue | Q21: Cyber Security | R21: 315593 | S21: 350303 | T21: 665896
B22: Payment status | D22: students | I22: Hybrid | J22: 685 | M22: Jan | N22: 785223 | Q22: Data Analytics | R22: 140967 | S22: 224186 | T22: 365153
B23: Cleared | D23: =COUNTIF(Enrollment_Data!K:K,"cleared") -> 214 | I23: Offline | J23: 668 | M23: Feb | N23: 787157 | Q23: Digital Marketing | R23: 125237 | S23: 181929 | T23: 307166
B24: Ongoing | D24: =COUNTIF(Enrollment_Data!K:K,"Ongoing") -> 1786 | I24: Online | J24: 647 | M24: Mar | N24: 668857 | Q24: Financial Accounting | R24: 141585 | S24: 133847 | T24: 275432
I25: Grand Total | J25: 2000 | M25: Apr | N25: 703982 | Q25: Logistics & Supply Chain | R25: 169667 | S25: 102668 | T25: 272335
B26: PERCENTAGE OF COMPLETED STUDENTS | E26: =(F17/F2)*100 -> 49.65 | M26: May | N26: 718073 | Q26: Power BI & Business Intelligence | R26: 96950 | S26: 105385 | T26: 202335
B27: PERCENTAGE OF ONGOING STUDENTS | E27: =F18/F2*100 -> 50.35 | H27: 4 | I27: Course wise Enrollment | M27: Jun | N27: 673453 | Q27: Project Management | R27: 135261 | S27: 134123 | T27: 269384
I28: Row Labels | J28: Count of Student_ID | M28: Jul | N28: 769688 | Q28: Python for Data Analysis | R28: 109321 | S28: 117599 | T28: 226920
I29: AI Generalist | J29: 134 | M29: Aug | N29: 827722 | Q29: Quantity Surveying (QS) | R29: 172967 | S29: 143681 | T29: 316648
I30: Financial Accounting | J30: 138 | M30: Sep | N30: 831971 | Q30: SAP FICO | R30: 200242 | S30: 253524 | T30: 453766
D31: Instructor by Enrollment | I31: Logistics & Supply Chain | J31: 140 | M31: Oct | N31: 778108 | Q31: SAP MM | R31: 170309 | S31: 289970 | T31: 460279
D32: Row Labels | E32: Count of Student_ID | I32: Power BI & Business Intelligence | J32: 142 | M32: Nov | N32: 804913 | Q32: UAE VAT & Taxation | R32: 111990 | S32: 82165 | T32: 194155
D33: Ahmed Khan | E33: 124 | I33: Quantity Surveying (QS) | J33: 151 | M33: Dec | N33: 793596 | Q33: Grand Total | R33: 2276202 | S33: 2504508 | T33: 4780710
D34: Aisha Rahman | E34: 140 | I34: Digital Marketing | J34: 156 | M34: Grand Total | N34: 9142743
D35: Ali Hassan | E35: 153 | I35: Python for Data Analysis | J35: 157
D36: Daniel George | E36: 121 | I36: Corporate Administration (ATCA) | J36: 158 | L36: 8 | M36: Revenue Generated by Branch and pending Revenue
D37: Fatima Noor | E37: 137 | I37: Cyber Security | J37: 158 | M37: Row Labels | N37: Sum of Revenue | O37: Sum of pending Revenue
D38: Hassan Ali | E38: 144 | I38: Data Analytics | J38: 159 | M38: Abu Dhabi | N38: 1648335 | O38: 879346 | P38: =M38 -> Abu Dhabi | Q38: =GETPIVOTDATA("Sum of Revenue",$M$37,"Branch","Abu Dhabi") -> 1648335
D39: John Mathew | E39: 130 | I39: Grand Total | J39: 1493 | M39: Sharjah | N39: 1576710 | O39: 781842 | P39: =M39 -> Sharjah
D40: Khalid Omar | E40: 139 | M40: Al Ain | N40: 1564026 | O40: 850377 | P40: =M40 -> Al Ain
D41: Lina George | E41: 125 | M41: Ras Al Khaimah | N41: 1488258 | O41: 684396 | P41: =M41 -> Ras Al Khaimah
...

Sheet  CHARTS FOR ENROLLMENT
I1: CHARTS

Sheet CHARTS FOR REVENUE
H1: CHARTS FOR REVENUE

Sheet DASHBOARD1

Sheet REVENUE ANALYSIS
